<!DOCTYPE html>
<html>
 <head>
  <meta charset="utf-8" />
  <title>Is there a bug with Exceptions inside a Forever loop? - Forums - ASM Community</title>
  <link rel="stylesheet" type="text/css" href="../../../style.css" />
  <link rel="canonical" href="../?id=20083" />
     </head>
 <body>
  <div id="header">
   <h1><a href="../../../">ASM Community</a></h1>
  </div>
  <div id="content">
   <p class="breadcrumbs"><a href="../../../">Home</a> &raquo; <a href="../../">Forums</a> &raquo; <a href="../../board/?id=47">Assemblers</a> &raquo; <a href="../?id=20083">Is there a bug with Exceptions inside a Forever loop?</a></p>
   <div class="post" id="post-153906">
    <div class="subject"><a href="#post-153906">Is there a bug with Exceptions inside a Forever loop?</a></div>
    <div class="body">Hi guys,<br /><br />after reading some AoA's sections, I've an issue when I try to catch some exceptions inside a forever loop.<br />The thing is: although the exceptions catchs are declared inside the forever loop, when the loop exits and then other code are performed, it's possible to catch the exceptions declared befor again... but, like I said, the exceptions were declared just inside the forever loop!<br /><br />Here is the code:<br /><pre><code>program p2_8_8;<br />#include&#40; &quot;stdlib.hhf&quot; &#41;<br />var <br />	i8&#58; int8;<br />	i16&#58; int16;	<br />	<br />begin p2_8_8;<br />	forever<br />		try<br />			stdout.put&#40;&quot;Please, enter an integer between -128 and 127&#58; &quot;&#41;;<br />			stdin.geti8&#40;&#41;;<br />			mov&#40;al,i8&#41;;<br />			break;<br />			exception &#40;ex.ConversionError&#41;;<br />				stdout.put&#40;&quot;The entered value is not a valid Integer!&quot;,nl&#41;;<br />			exception &#40;ex.ValueOutOfRange&#41;;<br />				stdout.put&#40;&quot;The entered value is not in specified range!&quot;,nl&#41;;<br />		endtry;<br />	endfor;<br />	stdout.put&#40;&quot;Please, enter an integer between -32768..32767&#58; &quot;&#41;;<br />	stdin.geti16&#40;&#41;;<br />	mov&#40;ax,i16&#41;;<br />	stdout.put<br />	&#40;<br />		&quot;Entered values were&#58; &quot;,nl,<br />		i8&#58;12, nl,<br />		i16&#58;12, nl<br />	&#41;;	<br />end p2_8_8;</code></pre><br /><br />If I wasn't very clear... please forget me  :oops: <br /><br />Regards,<br /><br />Carlos.</div>
    <div class="meta">Posted on 2004-12-08 12:26:15 by cmontemu</div>
   </div>
   <div class="post" id="post-153919">
    <div class="subject"><a href="#post-153919">Is there a bug with Exceptions inside a Forever loop?</a></div>
    <div class="body">Hi Carlos,<br /><br />insert an <strong>unprotected</strong> statement do the trick<br /><br /><pre><code><br />      ...<br />      try <br />         stdout.put&#40;&quot;Please, enter an integer between -128 and 127&#58; &quot;&#41;; <br />         stdin.geti8&#40;&#41;; <br />         mov&#40;al,i8&#41;; <br />         unprotected<br />         break; <br />         exception &#40;ex.ConversionError&#41;; <br />            stdout.put&#40;&quot;The entered value is not a valid Integer!&quot;,nl&#41;; <br />         exception &#40;ex.ValueOutOfRange&#41;; <br />            stdout.put&#40;&quot;The entered value is not in specified range!&quot;,nl&#41;; <br />      endtry;<br />      ...<br /></code></pre><br />for more info read <a target="_blank" href="http://webster.cs.ucr.edu/AoA/Windows/HTML/AdvancedControlStructures.html#998406">http://webster.cs.ucr.edu/AoA/Windows/HTML/AdvancedControlStructures.html#998406</a></div>
    <div class="meta">Posted on 2004-12-08 17:11:03 by arlequin</div>
   </div>
  </div>
 </body>
</html>